<?xml version="1.0" ?>
<robot name="Cobot_urdf" xmlns:xacro="http://www.ros.org/wiki/xacro">

  <xacro:include filename="$(find Cobot_urdf_description)/urdf/materials.xacro" />
  <xacro:include filename="$(find Cobot_urdf_description)/urdf/Cobot_urdf.trans" />
  <xacro:include filename="$(find Cobot_urdf_description)/urdf/Cobot_urdf.gazebo" />
  <link name="base_link">
    <inertial>
      <origin xyz="-4.837524950520688e-15 0.0 0.05662412059197525" rpy="0 0 0"/>
      <mass value="5.071711117972784"/>
      <inertia ixx="0.0253" iyy="0.0253" izz="0.019845" ixy="-0.0" iyz="0.0" ixz="-0.0"/>
    </inertial>
    <visual>
      <origin xyz="0 0 0" rpy="0 0 0"/>
      <geometry>
        <mesh filename="file://$(find Cobot_urdf_description)/meshes/base_link.stl" scale="0.001 0.001 0.001"/>
      </geometry>
      <material name="silver"/>
    </visual>
    <collision>
      <origin xyz="0 0 0" rpy="0 0 0"/>
      <geometry>
        <mesh filename="file://$(find Cobot_urdf_description)/meshes/base_link.stl" scale="0.001 0.001 0.001"/>
      </geometry>
    </collision>
  </link>

  <link name="pivot_1">
    <inertial>
      <origin xyz="7.689275524127196e-14 2.5194218624269975e-17 0.05204520883082267" rpy="0 0 0"/>
      <mass value="2.02878299192022"/>
      <inertia ixx="0.0059" iyy="0.005272" izz="0.004006" ixy="0.0" iyz="-0.0" ixz="-0.0"/>
    </inertial>
    <visual>
      <origin xyz="-0.0 -0.0 -0.212" rpy="0 0 0"/>
      <geometry>
        <mesh filename="file://$(find Cobot_urdf_description)/meshes/pivot_1.stl" scale="0.001 0.001 0.001"/>
      </geometry>
      <material name="silver"/>
    </visual>
    <collision>
      <origin xyz="-0.0 -0.0 -0.212" rpy="0 0 0"/>
      <geometry>
        <mesh filename="file://$(find Cobot_urdf_description)/meshes/pivot_1.stl" scale="0.001 0.001 0.001"/>
      </geometry>
    </collision>
  </link>

  <link name="arm_connector_1">
    <inertial>
      <origin xyz="-2.2338052083804137e-18 -0.045 -5.551115123125783e-17" rpy="0 0 0"/>
      <mass value="0.4993954221962672"/>
      <inertia ixx="0.000365" iyy="5.6e-05" izz="0.000365" ixy="0.0" iyz="0.0" ixz="-0.0"/>
    </inertial>
    <visual>
      <origin xyz="0.0 -0.045 -0.318" rpy="0 0 0"/>
      <geometry>
        <mesh filename="file://$(find Cobot_urdf_description)/meshes/arm_connector_1.stl" scale="0.001 0.001 0.001"/>
      </geometry>
      <material name="silver"/>
    </visual>
    <collision>
      <origin xyz="0.0 -0.045 -0.318" rpy="0 0 0"/>
      <geometry>
        <mesh filename="file://$(find Cobot_urdf_description)/meshes/arm_connector_1.stl" scale="0.001 0.001 0.001"/>
      </geometry>
    </collision>
  </link>

  <link name="shoulder_1">
    <inertial>
      <origin xyz="0.03854757809417635 -0.04495432445489295 0.038547578100873336" rpy="0 0 0"/>
      <mass value="1.9594013445092218"/>
      <inertia ixx="0.009554" iyy="0.018312" izz="0.009554" ixy="-8e-06" iyz="-8e-06" ixz="-0.007485"/>
    </inertial>
    <visual>
      <origin xyz="0.0 -0.045 -0.318" rpy="0 0 0"/>
      <geometry>
        <mesh filename="file://$(find Cobot_urdf_description)/meshes/shoulder_1.stl" scale="0.001 0.001 0.001"/>
      </geometry>
      <material name="silver"/>
    </visual>
    <collision>
      <origin xyz="0.0 -0.045 -0.318" rpy="0 0 0"/>
      <geometry>
        <mesh filename="file://$(find Cobot_urdf_description)/meshes/shoulder_1.stl" scale="0.001 0.001 0.001"/>
      </geometry>
    </collision>
  </link>

  <link name="shoulder_stepper_motor_1">
    <inertial>
      <origin xyz="3.1803689015674763e-07 -0.03671004791992677 3.180368724486904e-07" rpy="0 0 0"/>
      <mass value="2.3763102897230572"/>
      <inertia ixx="0.002096" iyy="0.002199" izz="0.002096" ixy="0.0" iyz="0.0" ixz="-0.0"/>
    </inertial>
    <visual>
      <origin xyz="-0.111369 0.003 -0.429369" rpy="0 0 0"/>
      <geometry>
        <mesh filename="file://$(find Cobot_urdf_description)/meshes/shoulder_stepper_motor_1.stl" scale="0.001 0.001 0.001"/>
      </geometry>
      <material name="silver"/>
    </visual>
    <collision>
      <origin xyz="-0.111369 0.003 -0.429369" rpy="0 0 0"/>
      <geometry>
        <mesh filename="file://$(find Cobot_urdf_description)/meshes/shoulder_stepper_motor_1.stl" scale="0.001 0.001 0.001"/>
      </geometry>
    </collision>
  </link>

  <link name="shoulder_spur_gear25_1">
    <inertial>
      <origin xyz="1.7326740353040826e-06 -0.004503182368978804 -6.689687163441427e-06" rpy="0 0 0"/>
      <mass value="0.007304287335988435"/>
      <inertia ixx="0.0" iyy="1e-06" izz="0.0" ixy="-0.0" iyz="0.0" ixz="-0.0"/>
    </inertial>
    <visual>
      <origin xyz="-0.111369 -0.019 -0.429369" rpy="0 0 0"/>
      <geometry>
        <mesh filename="file://$(find Cobot_urdf_description)/meshes/shoulder_spur_gear25_1.stl" scale="0.001 0.001 0.001"/>
      </geometry>
      <material name="silver"/>
    </visual>
    <collision>
      <origin xyz="-0.111369 -0.019 -0.429369" rpy="0 0 0"/>
      <geometry>
        <mesh filename="file://$(find Cobot_urdf_description)/meshes/shoulder_spur_gear25_1.stl" scale="0.001 0.001 0.001"/>
      </geometry>
    </collision>
  </link>

  <link name="wrist_1">
    <inertial>
      <origin xyz="0.07531143194539208 -0.022129949439698177 1.6527886922301782e-05" rpy="0 0 0"/>
      <mass value="0.3358041630457596"/>
      <inertia ixx="0.000157" iyy="0.001532" izz="0.001391" ixy="2.6e-05" iyz="-0.0" ixz="0.0"/>
    </inertial>
    <visual>
      <origin xyz="-0.199758 -0.046 -0.517758" rpy="0 0 0"/>
      <geometry>
        <mesh filename="file://$(find Cobot_urdf_description)/meshes/wrist_1.stl" scale="0.001 0.001 0.001"/>
      </geometry>
      <material name="silver"/>
    </visual>
    <collision>
      <origin xyz="-0.199758 -0.046 -0.517758" rpy="0 0 0"/>
      <geometry>
        <mesh filename="file://$(find Cobot_urdf_description)/meshes/wrist_1.stl" scale="0.001 0.001 0.001"/>
      </geometry>
    </collision>
  </link>

  <link name="wrist_stepper_motor_1">
    <inertial>
      <origin xyz="-3.343156671775649e-07 0.028582945134838292 -3.343164963753864e-07" rpy="0 0 0"/>
      <mass value="0.9990957119962105"/>
      <inertia ixx="0.000466" iyy="0.000539" izz="0.000513" ixy="-0.0" iyz="-0.0" ixz="-0.0"/>
    </inertial>
    <visual>
      <origin xyz="-0.244758 -0.024 -0.517758" rpy="0 0 0"/>
      <geometry>
        <mesh filename="file://$(find Cobot_urdf_description)/meshes/wrist_stepper_motor_1.stl" scale="0.001 0.001 0.001"/>
      </geometry>
      <material name="silver"/>
    </visual>
    <collision>
      <origin xyz="-0.244758 -0.024 -0.517758" rpy="0 0 0"/>
      <geometry>
        <mesh filename="file://$(find Cobot_urdf_description)/meshes/wrist_stepper_motor_1.stl" scale="0.001 0.001 0.001"/>
      </geometry>
    </collision>
  </link>

  <link name="shoulder_connector_1">
    <inertial>
      <origin xyz="1.8474749538310853e-05 -0.000541609723718927 -9.184698235797928e-06" rpy="0 0 0"/>
      <mass value="0.17104414025327175"/>
      <inertia ixx="0.000104" iyy="0.000193" izz="0.000104" ixy="0.0" iyz="-0.0" ixz="-0.0"/>
    </inertial>
    <visual>
      <origin xyz="-0.155563 -0.013 -0.473563" rpy="0 0 0"/>
      <geometry>
        <mesh filename="file://$(find Cobot_urdf_description)/meshes/shoulder_connector_1.stl" scale="0.001 0.001 0.001"/>
      </geometry>
      <material name="silver"/>
    </visual>
    <collision>
      <origin xyz="-0.155563 -0.013 -0.473563" rpy="0 0 0"/>
      <geometry>
        <mesh filename="file://$(find Cobot_urdf_description)/meshes/shoulder_connector_1.stl" scale="0.001 0.001 0.001"/>
      </geometry>
    </collision>
  </link>

  <link name="shoulder_spur_gear100_1">
    <inertial>
      <origin xyz="-3.4021700265340904e-07 -0.016264837965520224 -3.30411271676212e-07" rpy="0 0 0"/>
      <mass value="0.17788315102985092"/>
      <inertia ixx="0.000123" iyy="0.000192" izz="0.000123" ixy="-0.0" iyz="0.0" ixz="0.0"/>
    </inertial>
    <visual>
      <origin xyz="-0.199758 -0.01 -0.517758" rpy="0 0 0"/>
      <geometry>
        <mesh filename="file://$(find Cobot_urdf_description)/meshes/shoulder_spur_gear100_1.stl" scale="0.001 0.001 0.001"/>
      </geometry>
      <material name="silver"/>
    </visual>
    <collision>
      <origin xyz="-0.199758 -0.01 -0.517758" rpy="0 0 0"/>
      <geometry>
        <mesh filename="file://$(find Cobot_urdf_description)/meshes/shoulder_spur_gear100_1.stl" scale="0.001 0.001 0.001"/>
      </geometry>
    </collision>
  </link>

  <link name="wrist_spur_gear_25_1">
    <inertial>
      <origin xyz="-3.3652765843439347e-07 0.0024999996757781497 -3.3827339751546504e-07" rpy="0 0 0"/>
      <mass value="0.014725922228793773"/>
      <inertia ixx="1e-06" iyy="1e-06" izz="1e-06" ixy="-0.0" iyz="-0.0" ixz="-0.0"/>
    </inertial>
    <visual>
      <origin xyz="-0.244758 -0.01 -0.517758" rpy="0 0 0"/>
      <geometry>
        <mesh filename="file://$(find Cobot_urdf_description)/meshes/wrist_spur_gear_25_1.stl" scale="0.001 0.001 0.001"/>
      </geometry>
      <material name="silver"/>
    </visual>
    <collision>
      <origin xyz="-0.244758 -0.01 -0.517758" rpy="0 0 0"/>
      <geometry>
        <mesh filename="file://$(find Cobot_urdf_description)/meshes/wrist_spur_gear_25_1.stl" scale="0.001 0.001 0.001"/>
      </geometry>
    </collision>
  </link>

  <link name="wrist_connector_1">
    <inertial>
      <origin xyz="0.00026064933688008107 0.0005414455748674173 0.0002523240587303244" rpy="0 0 0"/>
      <mass value="0.17103995328737515"/>
      <inertia ixx="0.000104" iyy="0.000193" izz="0.000104" ixy="-0.0" iyz="-0.0" ixz="0.0"/>
    </inertial>
    <visual>
      <origin xyz="-0.307015 -0.014 -0.517515" rpy="0 0 0"/>
      <geometry>
        <mesh filename="file://$(find Cobot_urdf_description)/meshes/wrist_connector_1.stl" scale="0.001 0.001 0.001"/>
      </geometry>
      <material name="silver"/>
    </visual>
    <collision>
      <origin xyz="-0.307015 -0.014 -0.517515" rpy="0 0 0"/>
      <geometry>
        <mesh filename="file://$(find Cobot_urdf_description)/meshes/wrist_connector_1.stl" scale="0.001 0.001 0.001"/>
      </geometry>
    </collision>
  </link>

  <link name="wrist_spur_gear_100_1">
    <inertial>
      <origin xyz="0.00024284883696423787 0.009129228527040893 0.000242677866239549" rpy="0 0 0"/>
      <mass value="0.1783268128470493"/>
      <inertia ixx="0.000124" iyy="0.000192" izz="0.000124" ixy="0.0" iyz="0.0" ixz="-0.0"/>
    </inertial>
    <visual>
      <origin xyz="-0.369515 -0.024 -0.517515" rpy="0 0 0"/>
      <geometry>
        <mesh filename="file://$(find Cobot_urdf_description)/meshes/wrist_spur_gear_100_1.stl" scale="0.001 0.001 0.001"/>
      </geometry>
      <material name="silver"/>
    </visual>
    <collision>
      <origin xyz="-0.369515 -0.024 -0.517515" rpy="0 0 0"/>
      <geometry>
        <mesh filename="file://$(find Cobot_urdf_description)/meshes/wrist_spur_gear_100_1.stl" scale="0.001 0.001 0.001"/>
      </geometry>
    </collision>
  </link>

  <link name="gripper_1">
    <inertial>
      <origin xyz="0.0432500058148505 0.017169383430160105 2.3414949423816722e-08" rpy="0 0 0"/>
      <mass value="0.2953288884565428"/>
      <inertia ixx="0.00014" iyy="0.000511" izz="0.000487" ixy="5.6e-05" iyz="0.0" ixz="0.0"/>
    </inertial>
    <visual>
      <origin xyz="-0.369758 0.022 -0.517758" rpy="0 0 0"/>
      <geometry>
        <mesh filename="file://$(find Cobot_urdf_description)/meshes/gripper_1.stl" scale="0.001 0.001 0.001"/>
      </geometry>
      <material name="silver"/>
    </visual>
    <collision>
      <origin xyz="-0.369758 0.022 -0.517758" rpy="0 0 0"/>
      <geometry>
        <mesh filename="file://$(find Cobot_urdf_description)/meshes/gripper_1.stl" scale="0.001 0.001 0.001"/>
      </geometry>
    </collision>
  </link>

  <joint name="Revolute 36" type="continuous">
    <origin xyz="0.0 0.0 0.212" rpy="0 0 0"/>
    <parent link="base_link"/>
    <child link="pivot_1"/>
    <axis xyz="0.0 0.0 -1.0"/>
  </joint>

  <joint name="Rigid 37" type="fixed">
    <origin xyz="-0.0 0.045 0.106" rpy="0 0 0"/>
    <parent link="pivot_1"/>
    <child link="arm_connector_1"/>
  </joint>

  <joint name="Revolute 38" type="continuous">
    <origin xyz="0.0 0.0 0.0" rpy="0 0 0"/>
    <parent link="arm_connector_1"/>
    <child link="shoulder_1"/>
    <axis xyz="0.0 1.0 0.0"/>
  </joint>

  <joint name="Rigid 39" type="fixed">
    <origin xyz="0.111369 -0.048 0.111369" rpy="0 0 0"/>
    <parent link="shoulder_1"/>
    <child link="shoulder_stepper_motor_1"/>
  </joint>

  <joint name="Rigid 40" type="fixed">
    <origin xyz="0.0 0.022 0.0" rpy="0 0 0"/>
    <parent link="shoulder_stepper_motor_1"/>
    <child link="shoulder_spur_gear25_1"/>
  </joint>

  <joint name="Revolute 41" type="continuous">
    <origin xyz="0.0 0.036 0.0" rpy="0 0 0"/>
    <parent link="shoulder_spur_gear100_1"/>
    <child link="wrist_1"/>
    <axis xyz="0.0 1.0 0.0"/>
  </joint>

  <joint name="Rigid 42" type="fixed">
    <origin xyz="0.045 -0.022 0.0" rpy="0 0 0"/>
    <parent link="wrist_1"/>
    <child link="wrist_stepper_motor_1"/>
  </joint>

  <joint name="Rigid 43" type="fixed">
    <origin xyz="0.155563 -0.032 0.155563" rpy="0 0 0"/>
    <parent link="shoulder_1"/>
    <child link="shoulder_connector_1"/>
  </joint>

  <joint name="Rigid 44" type="fixed">
    <origin xyz="0.199758 -0.035 0.199758" rpy="0 0 0"/>
    <parent link="shoulder_1"/>
    <child link="shoulder_spur_gear100_1"/>
  </joint>

  <joint name="Rigid 45" type="fixed">
    <origin xyz="0.0 -0.014 0.0" rpy="0 0 0"/>
    <parent link="wrist_stepper_motor_1"/>
    <child link="wrist_spur_gear_25_1"/>
  </joint>

  <joint name="Rigid 46" type="fixed">
    <origin xyz="0.107257 -0.032 -0.000243" rpy="0 0 0"/>
    <parent link="wrist_1"/>
    <child link="wrist_connector_1"/>
  </joint>

  <joint name="Rigid 47" type="fixed">
    <origin xyz="0.169757 -0.022 -0.000243" rpy="0 0 0"/>
    <parent link="wrist_1"/>
    <child link="wrist_spur_gear_100_1"/>
  </joint>

  <joint name="Revolute 48" type="continuous">
    <origin xyz="0.000243 -0.046 0.000243" rpy="0 0 0"/>
    <parent link="wrist_spur_gear_100_1"/>
    <child link="gripper_1"/>
    <axis xyz="0.0 -1.0 0.0"/>
  </joint>
  <ros2_control name="GazeboSimSystem" type="system">
    <hardware>
      <plugin>gazebo_ros2_control/GazeboSystem</plugin>
    </hardware>
    <joint name="Revolute 36">
      <command_interface name="position" />
      <state_interface name="position">
        <param name="initial_value">0.0</param>
      </state_interface>
      <state_interface name="velocity" />
    </joint>
    <joint name="Revolute 38">
      <command_interface name="position" />
      <state_interface name="position">
        <param name="initial_value">0.0</param>
      </state_interface>
      <state_interface name="velocity" />
    </joint>
    <joint name="Revolute 41">
      <command_interface name="position" />
      <state_interface name="position">
        <param name="initial_value">0.0</param>
      </state_interface>
      <state_interface name="velocity" />
    </joint>
    <joint name="Revolute 48">
      <command_interface name="position" />
      <state_interface name="position">
        <param name="initial_value">0.0</param>
      </state_interface>
      <state_interface name="velocity" />
    </joint>
  </ros2_control>
  <gazebo>
    <plugin name="gazebo_ros2_control" filename="libgazebo_ros2_control.so">
      <parameters>$(find Cobot_urdf_description)/config/cobot_controller.yaml)</parameters>
    </plugin>
  </gazebo>
</robot>
